Workbook

Sheet 0_README
A1: Day 22 — Monetization Model (Cost/Job → Giá → Value Metric → Kênh → Evidence)
A2: SẢN PHẨM GIẢ ĐỊNH (placeholder) — "HoaDonAI": AI nhập liệu và đối chiếu hóa đơn đầu vào cho SME Việt Nam. Thay các ô VÀNG bằng số liệu sản phẩm thật của bạn; mọi ô xám tự tính lại.
A4: Quy ước màu
A5: Vàng | B5: Ô bạn phải điền (chữ xanh dương = số nhập tay)
A6: Xám | B6: Công thức tự tính — không sửa
A7: Xanh lá | B7: Đạt ngưỡng
A8: Vàng cam | B8: Sát ngưỡng / cần kế hoạch cải thiện
A9: Đỏ | B9: Không đạt — quay lại sửa GIẢ ĐỊNH, không sửa giá cho đẹp
A11: Thứ tự làm và bản đồ tab
A12: 1_Cost_Job | B12: Tab nặng nhất — Cost/Job đủ 5 thành phần (S1–S8), hai biến thể HITL, Batch/cache.
A13: 2_Pricing | B13: Giá sàn, giá trần, giá đề xuất, Gross Margin, breakeven containment, sensitivity, stress test.
A14: 3_Value_Metric | B14: Chấm Attribution × Autonomy → Value Metric + Decision Note + 2 benchmark có link.
A15: 4_Channel_Fit | B15: Ngân sách CAC, deal/AE/ngày, CAC thực, scorecard, chốt 1 kênh.
A16: 5_90Day_Plan | B16: Pain Moment, kế hoạch 90 ngày, checklist Evidence Pack.
A17: 6_Benchmarks | B17: Bảng giá tham chiếu CÓ NGUỒN và NGÀY KIỂM TRA — chỉ đọc.
A19: Quy ước mô hình (đọc trước khi chạm vào con số nào)
A20: Mẫu số của Cost/Job là số job HOÀN THÀNH (job AI tự làm xong), không phải job thử.
A21: Cost/Job "headline" = COGS (API + Infra + HITL + Retry). Overhead (thành phần thứ 5) được tính riêng và hiện ở dòng "có overhead", theo gợi ý của đề: "thường để riêng khi tính GM".
A22: Biến thể HITL đang chọn: A (khách tự xử lý ca escalate). Biến thể B (bạn gánh) được tính song song để so sánh. Đổi ở 1_Cost_Job ô "Biến thể HITL".
A23: Giá API lấy từ 6_Benchmarks, ngày kiểm tra 13/10/2026. Không dùng giá khuyến mại nào trong base case.
A24: Số liệu đầu vào đánh dấu "GIẢ ĐỊNH" / "ƯỚC TÍNH" là CHƯA ĐO. Mỗi con số trong One-Pager truy được về một ô ở đây.
A26: Dashboard — 5 con số Trạm 3 + kênh Trạm 4
A27: Cost/Job | B27: ='2_Pricing'!$B$96 -> 0.037871708 | C27: $ / job | D27: 2_Pricing mục "5 CON SỐ".
A28: Giá sàn (3 × Cost/Job) | B28: ='2_Pricing'!$B$97 -> 0.11361512 | C28: $ / job
A29: Giá bán đề xuất (hiệu dụng) | B29: ='2_Pricing'!$B$98 -> 0.12417582 | C29: $ / job
A30: Gross Margin | B30: ='2_Pricing'!$B$99 -> 0.69501545 | C30: % | D30: Mục tiêu ≥ 60%.
A31: Breakeven containment | B31: ='2_Pricing'!$B$100 -> 0.5746103 | C31: %
A32: so với eval hiện tại (ước tính) | B32: ='2_Pricing'!$B$101 -> 0.8 | C32: %
A33: Ngân sách CAC / khách | B33: ='4_Channel_Fit'!$B$46 -> 538.53769 | C33: $
A34: Số deal / AE / ngày | B34: ='4_Channel_Fit'!$B$47 -> 2.5811209 | C34: deal
A35: Kênh đã chốt | B35: ='4_Channel_Fit'!$B$38 -> PLG
A37: Final Checklist trước khi nộp (§5.8) — ô tự kiểm
A38: 1. Tab 1 — đủ 5 thành phần chi phí, không ô nào trống vô lý | B38: ='1_Cost_Job'!$B$99 -> ✓ Đủ API, Infra, HITL, Retry, Overhead đều > 0. Ô = 0 duy nhất: Speech (không có thoại) và escalation Biến thể A (khách tự xử lý), cả hai có lý do ghi chú.
A39: 2. Tab 1 — mẫu số là JOB HOÀN THÀNH | B39: =IF(ABS('1_Cost_Job'!$B$96/'1_Cost_Job'!$B$23-'1_Cost_Job'!$B$94)<0.0000001,"✓ Cost/Job = COGS / số job hoàn thành","✗ Mẫu số sai") -> ✓ Cost/Job = COGS / số job hoàn thành
A40: 3. Tab 2 — giá bán ≥ 3 × Cost/Job và GM ≥ 60% | B40: =IF(AND('2_Pricing'!$B$38>='2_Pricing'!$B$7,'2_Pricing'!$B$48>='2_Pricing'!$B$45,'2_Pricing'!$B$48<=0.85),"✓ Giá ≥ giá sàn và GM trong vùng 60–85%","✗ Chưa đạt: xem 2_Pricing mục A và D") -> ✓ Giá ≥ giá sàn và GM trong vùng 60–85%
A41: 4. Tab 2 — Breakeven containment đã tính, đã so với eval | B41: =IF(AND(ISNUMBER('2_Pricing'!$B$64),ISNUMBER('2_Pricing'!$B$65)),"✓ Breakeven "&ROUND('2_Pricing'!$B$64*100,1)&"% so với "&ROUND('2_Pricing'!$B$65*100,1)&"% (eval hiện tại là ước tính, chưa đo)","✗ Thiếu") -> ✓ Breakeven 57.5% so với 80% (eval hiện tại là ước tính, chưa đo)
A42: 5. Tab 3 — Value Metric + Decision Note + 2 benchmark có link | B42: =IF(AND(LEN('3_Value_Metric'!$B$38)>0,LEFT('3_Value_Metric'!$B$45,4)="http",LEFT('3_Value_Metric'!$B$48,4)="http"),"✓ Có Value Metric, Decision Note và 2 link benchmark","✗ Thiếu") -> ✓ Có Value Metric, Decision Note và 2 link benchmark
A43: 6. Tab 4 — Ngân sách CAC, deal/AE/ngày, 1 kênh duy nhất | B43: =IF(AND(ISNUMBER('4_Channel_Fit'!$B$9),ISNUMBER('4_Channel_Fit'!$B$18),LEFT('4_Channel_Fit'!$B$38,4)<>"HÒA"),"✓ Đã chốt đúng 1 kênh: "&'4_Channel_Fit'!$B$38,"✗ Chưa chốt 1 kênh") -> ✓ Đã chốt đúng 1 kênh: PLG
A44: 7. Tab 5 — 90-day plan có số; Evidence Pack có deadline | B44: =IF(AND(ISNUMBER('5_90Day_Plan'!$D$36),ISNUMBER('5_90Day_Plan'!$D$37),ISNUMBER('5_90Day_Plan'!$D$38),ISNUMBER('5_90Day_Plan'!$B$19)),"✓ Plan có số; cả 3 tài sản Evidence Pack có deadline","✗ Thiếu số hoặc deadline") -> ✓ Plan có số; cả 3 tài sản Evidence Pack có deadline
A45: 8. Ghi ngày kiểm tra giá API ở 6_Benchmarks | B45: =IF(ISNUMBER('1_Cost_Job'!$B$6),"✓ Ngày kiểm tra giá: 13/10/2026 (cột H, 6_Benchmarks)","✗ Thiếu ngày") -> ✓ Ngày kiểm tra giá: 13/10/2026 (cột H, 6_Benchmarks)
...

Sheet 1_Cost_Job
A1: 1_Cost_Job — Cost/Job đủ 5 thành phần (tab nặng nhất)
A2: SẢN PHẨM GIẢ ĐỊNH (placeholder) — "HoaDonAI": AI nhập liệu và đối chiếu hóa đơn đầu vào cho SME Việt Nam. Thay các ô VÀNG bằng số liệu sản phẩm thật của bạn; mọi ô xám tự tính lại.
A4: S0. Tham số chung
A5: Tỷ giá | B5: 26250 | C5: VND / USD | D5: Trung bình 36 ngân hàng 06/07/2026 = 26.252 (webgia.com). Chưa có tỷ giá tháng 10/2026: cập nhật theo Vietcombank ngày nộp.
A6: Ngày kiểm tra giá API | B6: 46308 | C6: ngày | D6: Đã mở trang giá Anthropic và các vendor ngày này (xem 6_Benchmarks, cột "Ngày kiểm tra").
A7: Model LLM đang dùng | B7: Claude Sonnet 5.5 | C7: chọn | D7: Chọn từ danh sách ở 6_Benchmarks. Base case dùng Sonnet 5.5 (thận trọng cho bài toán kế toán); Haiku 5.5 là đòn bẩy giảm chi phí, xem bảng stress ở 2_Pricing.
A8: Biến thể HITL | B8: A | C8: A / B | D8: A = khách tự xử lý ca AI không chắc → không vào COGS của bạn. B = bạn giao kết quả, phải tự xử lý → vào thẳng COGS. Lý do chọn A ở S7.
A10: S1. Định nghĩa Job (1 câu — phải là thứ KHÁCH coi là giá trị)
A11: 1 job = | B11: 1 hóa đơn đầu vào được đọc, hạch toán đề xuất và đối chiếu xong, và kế toán của khách xác nhận hoặc không sửa lại trong 7 ngày.
A12: Ngân sách khách lấy tiền từ | B12: Nhân sự / Vận hành: chi phí nhân viên kế toán nhập liệu hoặc dịch vụ kế toán thuê ngoài (không phải ngân sách phần mềm).
A13: Ai ký duyệt | B13: Chủ doanh nghiệp SME hoặc kế toán trưởng.
A14: Phiên bản B — thay công việc đang có người làm (CHỌN) | B14: Thay công việc nhập liệu và đối chiếu hóa đơn đầu vào của kế toán SME: mỗi hóa đơn được hạch toán đề xuất, kế toán chỉ duyệt các ca AI không chắc.
B15: Phiên bản A (bị loại): "Nền tảng AI cho kế toán" → rơi vào ngân sách phần mềm, khách hỏi "tôi có cần thêm một nền tảng nữa không?".
A16: Kiểm tra 1: khách coi job này là giá trị? | B16: Có | D16: Hóa đơn xử lý xong là đơn vị công việc khách đang trả lương cho người làm.
A17: Kiểm tra 2: đếm được tự động? | B17: Có | D17: Mỗi job có ID và trạng thái cuối (completed / escalated) ghi log tự động.
A18: Kiểm tra 3: chặt như Intercom? | B18: Có | D18: Giống định nghĩa resolution của Intercom Fin: "khách xác nhận xong hoặc không hỏi lại".
A20: S2. Khối lượng
A21: Số job THỬ / tháng | B21: 10000 | C21: job | D21: GIẢ ĐỊNH: ~15 SME × ~650 hóa đơn/tháng. Phải khớp mục tiêu tháng 3 ở 5_90Day_Plan.
A22: Containment rate | B22: 0.8 | C22: % | D22: ƯỚC TÍNH THÔ, CHƯA ĐO — sẽ thay bằng kết quả eval (Evidence Pack, 5_90Day_Plan, deadline 10/11/2026). Containment = % job AI tự làm xong, không cần người.
A23: Số job HOÀN THÀNH / tháng | B23: =$B$21*$B$22 -> 8000 | C23: job | D23: MẪU SỐ của Cost/Job. Không phải số job thử.
A24: Số job chuyển sang người (escalate) / tháng | B24: =$B$21-$B$23 -> 2000 | C24: job
A26: S3. LLM — tách phần cache được và phần fresh
A27: Giá input | B27: =INDEX('6_Benchmarks'!$B$6:$B$12,MATCH($B$7,'6_Benchmarks'!$A$6:$A$12,0)) -> 2 | C27: $ / 1M token | D27: Tra từ 6_Benchmarks theo model đã chọn.
A28: Giá cache write (5 phút) | B28: =INDEX('6_Benchmarks'!$C$6:$C$12,MATCH($B$7,'6_Benchmarks'!$A$6:$A$12,0)) -> 2.5 | C28: $ / 1M token
A29: Giá cache read | B29: =INDEX('6_Benchmarks'!$D$6:$D$12,MATCH($B$7,'6_Benchmarks'!$A$6:$A$12,0)) -> 0.1 | C29: $ / 1M token
A30: Giá output | B30: =INDEX('6_Benchmarks'!$E$6:$E$12,MATCH($B$7,'6_Benchmarks'!$A$6:$A$12,0)) -> 10 | C30: $ / 1M token
A31: Giảm giá Batch API | B31: 0.5 | C31: % | D31: Anthropic: Batch giảm 50% input và output (trang giá 13/10/2026).
A32: Số lượt gọi LLM / job | B32: 2 | C32: lượt | D32: Lượt 1: đọc/trích xuất hóa đơn. Lượt 2: hạch toán đề xuất + đối chiếu. GIẢ ĐỊNH.
A33: Token input CACHE được / lượt | B33: 5000 | C33: token | D33: System prompt + hệ thống tài khoản kế toán + few-shot. GIẢ ĐỊNH.
A34: Token input FRESH / lượt | B34: 1500 | C34: token | D34: Nội dung hóa đơn (XML nhẹ, scan/ảnh nặng hơn). GIẢ ĐỊNH, cần đo.
A35: Token output / lượt | B35: 400 | C35: token | D35: JSON: trường dữ liệu + tài khoản đề xuất + độ tin cậy. GIẢ ĐỊNH.
A36: Số job xử lý chung trong 1 batch (chia sẻ 1 lần ghi cache) | B36: 25 | C36: job | D36: Khách upload cả lô hóa đơn mỗi ngày → cache 5 phút còn "nóng". Nếu job rời rạc, cache hit thấp hơn: đây là giả định nhạy.
A37: Số lệnh gọi / batch | B37: =$B$32*$B$36 -> 50 | C37: lệnh
A38: Chi phí phần cache / job | B38: =$B$33*($B$28+($B$37-1)*$B$29)/1000000/$B$36 -> 0.00148 | C38: $ / job | D38: 1 lần cache write + (số lệnh − 1) lần cache read, chia cho số job trong batch.
A39: Chi phí input fresh / job | B39: =$B$32*$B$34*$B$27/1000000 -> 0.006 | C39: $ / job
A40: Chi phí output / job | B40: =$B$32*$B$35*$B$30/1000000 -> 0.008 | C40: $ / job
A41: Chi phí LLM / job (CÓ cache) | B41: =$B$38+$B$39+$B$40 -> 0.01548 | C41: $ / job
A42: Chi phí LLM / job (KHÔNG cache) | B42: =$B$32*($B$33+$B$34)*$B$27/1000000+$B$40 -> 0.034 | C42: $ / job | D42: Tính đủ giá input cho cả phần lặp lại ở mọi lượt.
A43: % tiết kiệm nhờ cache | B43: =1-$B$41/$B$42 -> 0.54470588 | C43: % | D43: Đề: ghi lại % tiết kiệm. Worked example của đề ra ~38%; ở đây cao hơn vì 1 batch dùng chung 1 lần ghi cache.
A44: Chi phí LLM / job nếu dùng Batch API (số thứ hai) | B44: =$B$41*(1-$B$31) -> 0.00774 | C44: $ / job | D44: Job hóa đơn không cần realtime (giao kết quả trong ngày) → Batch khả thi. Lưu ý cache hit trong Batch chỉ là "best effort". Không dùng cho base case.
...

Sheet 2_Pricing
A1: 2_Pricing — Giá sàn, giá trần, Gross Margin, Breakeven containment, stress test
A2: SẢN PHẨM GIẢ ĐỊNH (placeholder) — "HoaDonAI": AI nhập liệu và đối chiếu hóa đơn đầu vào cho SME Việt Nam. Thay các ô VÀNG bằng số liệu sản phẩm thật của bạn; mọi ô xám tự tính lại.
A4: A. Giá sàn = 3 × Cost/Job
A5: Cost/Job (biến thể đang chọn) | B5: ='1_Cost_Job'!$B$94 -> 0.037871708 | C5: $ / job | D5: Liên kết từ 1_Cost_Job.
A6: Hệ số giá sàn | B6: 3 | C6: × | D6: Đủ để cover R&D, sales, support và sai số ước tính (đề §4.3).
A7: GIÁ SÀN | B7: =$B$6*$B$5 -> 0.11361512 | C7: $ / job
A8: Giá sàn quy đổi | B8: =$B$7*'1_Cost_Job'!$B$5 -> 2982.397 | C8: VND / job
A10: B. Giá trần — neo theo giá trị hoặc theo nhân công
A11: Lương 1 nhân viên nhập liệu bị thay thế | B11: 10000000 | C11: VND / tháng | D11: GIẢ ĐỊNH (lấy mức 10tr/tháng như ví dụ của đề). Cần xác minh qua phỏng vấn khách.
A12: Số hóa đơn 1 người xử lý được / tháng | B12: 1300 | C12: hóa đơn | D12: GIẢ ĐỊNH: ~60 hóa đơn/ngày × 22 ngày. Cần xác minh qua phỏng vấn khách.
A13: Chi phí người / hóa đơn | B13: =$B$11/$B$12 -> 7692.3077 | C13: VND / job | D13: Đây là thứ khách so sánh với giá của bạn — không phải ChatGPT $20.
A14: Neo nhân công — cận dưới | B14: 0.5 | C14: % lương | D14: Đề: charge 50–70% lương vị trí bị thay.
A15: Neo nhân công — cận trên | B15: 0.7 | C15: % lương
A16: Neo nhân công: giá / job (dưới) | B16: =$B$13*$B$14 -> 3846.1538 | C16: VND / job
A17: Neo nhân công: giá / job (trên) | B17: =$B$13*$B$15 -> 5384.6154 | C17: VND / job
A18: Giá trị khác / job (sai sót tránh được, phạt chậm nộp...) | B18: 0 | C18: VND / job | D18: CHƯA ĐO — không tính, nên neo giá trị chỉ gồm tiết kiệm nhân công. Ô = 0 có lý do.
A19: Neo giá trị — cận dưới | B19: 0.1 | C19: % giá trị | D19: Đề: charge 10–25% giá trị tạo ra.
A20: Neo giá trị — cận trên | B20: 0.25 | C20: % giá trị
A21: Neo giá trị: giá / job (dưới) | B21: =($B$13+$B$18)*$B$19 -> 769.23077 | C21: VND / job
A22: Neo giá trị: giá / job (trên) | B22: =($B$13+$B$18)*$B$20 -> 1923.0769 | C22: VND / job
A23: Chênh nhau giữa hai neo (cận trên) | B23: =$B$17/$B$22 -> 2.8 | C23: × | D23: Chênh nhiều → đề: chọn cái khách dễ tự kiểm chứng nhất.
A24: Neo đã chọn | B24: Nhân công | C24: chọn | D24: Lý do bên dưới.
A25: Lý do chọn neo | B25: ="Tôi neo giá theo lương người nhập liệu vì khách tự kiểm tra được con số này trên bảng lương của họ. ""Giá trị AI tạo ra"" thì họ phải tin vào ước tính của tôi. Giá đề xuất "&ROUND($B$37,0)&" đ/hóa đơn rẻ hơn thuê người khoảng "&ROUND($B$40*100,0)&"%, nằm giữa giá sàn ("&ROUND($B$8,0)&" đ) và giá trần ("&ROUND($B$27,0)&" đ)." -> Tôi neo giá theo lương người nhập liệu vì khách tự kiểm tra được con số này trên bảng lương của họ. "Giá trị AI tạo ra" thì họ phải tin vào ước tính của tôi. Giá đề xuất 3260 đ/hóa đơn rẻ hơn thuê người khoảng 58%, nằm giữa giá sàn (2982 đ) và giá trần (5385 đ).
B26: Lưu ý: neo giá trị cho giá trần THẤP HƠN giá sàn, nên đòn bẩy giảm Cost/Job (bảng model ở mục G) quan trọng hơn chuyện tăng giá.
A27: GIÁ TRẦN (theo neo đã chọn, cận trên) | B27: =IF($B$24="Nhân công",$B$17,$B$22) -> 5384.6154 | C27: VND / job
A28: Giá trần quy đổi | B28: =$B$27/'1_Cost_Job'!$B$5 -> 0.20512821 | C28: $ / job
A30: C. Giá bán đề xuất — Hybrid (phí nền + theo hóa đơn hoàn thành vượt gói)
A31: Phí nền / tháng | B31: 1100000 | C31: VND / khách | D31: Đổi lấy thứ cụ thể: kết nối phần mềm kế toán + SLA xử lý trong ngày + hạn mức hóa đơn trong gói.
A32: Số hóa đơn hoàn thành gồm trong gói | B32: 350 | C32: hóa đơn
A33: Giá mỗi hóa đơn hoàn thành vượt gói | B33: 3500 | C33: VND / job | D33: Chỉ tính hóa đơn HOÀN THÀNH theo định nghĩa job ở 1_Cost_Job S1.
A34: Hóa đơn hoàn thành / khách / tháng (điển hình) | B34: 520 | C34: job | D34: = 650 hóa đơn thử × containment 80%. GIẢ ĐỊNH, cần xác minh với khách pilot.
A35: Doanh thu / khách / tháng | B35: =$B$31+MAX(0,$B$34-$B$32)*$B$33 -> 1695000 | C35: VND
A36: ARPU / tháng | B36: =$B$35/'1_Cost_Job'!$B$5 -> 64.571429 | C36: $ / tháng | D36: Dùng cho 4_Channel_Fit.
A37: Giá hiệu dụng / job hoàn thành | B37: =$B$35/$B$34 -> 3259.6154 | C37: VND / job
A38: GIÁ BÁN ĐỀ XUẤT (hiệu dụng) | B38: =$B$37/'1_Cost_Job'!$B$5 -> 0.12417582 | C38: $ / job
A39: Hóa đơn thử / khách / tháng | B39: =$B$34/'1_Cost_Job'!$B$22 -> 650 | C39: job
A40: Rẻ hơn thuê người | B40: =1-$B$37/$B$13 -> 0.57625 | C40: % | D40: Đây là câu trả lời cho khách: so với lương nhân viên.
A41: Giá ≥ giá sàn (3 × Cost/Job)? | B41: =IF($B$38>=$B$7,"✓ Giá đề xuất ≥ giá sàn","✗ Giá đề xuất < giá sàn — quay lại Tab 1, đừng sửa giá cho đẹp") -> ✓ Giá đề xuất ≥ giá sàn
A42: Giá ≤ giá trần? | B42: =IF($B$38<=$B$28,"✓ Giá đề xuất nằm trong vùng giá bán (sàn → trần)","~ Giá đề xuất vượt giá trần theo neo đã chọn") -> ✓ Giá đề xuất nằm trong vùng giá bán (sàn → trần)
A44: D. Gross Margin
...

Sheet 3_Value_Metric
A1: 3_Value_Metric — Attribution × Autonomy → Value Metric
A2: SẢN PHẨM GIẢ ĐỊNH (placeholder) — "HoaDonAI": AI nhập liệu và đối chiếu hóa đơn đầu vào cho SME Việt Nam. Thay các ô VÀNG bằng số liệu sản phẩm thật của bạn; mọi ô xám tự tính lại. Chấm theo thực tế HÔM NAY, không theo kế hoạch quý sau.
A4: Attribution — đo được kết quả này do AI tạo ra không? (chấm 1–5)
A5: A1. Mỗi job có ID và trạng thái cuối ghi log tự động? | B5: 4 | D5: Thiết kế đã có (completed / escalated / sửa lại ≤ 7 ngày); chưa chạy ở quy mô khách thật.
A6: A2. Định nghĩa "hoàn thành" đo tự động được? | B6: 4 | D6: Có: kế toán xác nhận hoặc không sửa trong 7 ngày — log được bằng sự kiện trong sản phẩm.
A7: A3. Có bộ eval ≥ 200 mẫu gán nhãn, chạy lại mỗi lần đổi model/prompt? | B7: 2 | D7: CHƯA có. Kế hoạch 300 mẫu, deadline 10/11/2026 (Evidence Pack).
A8: A4. Có baseline trước-AI của khách (thời gian/hóa đơn, tỷ lệ sai)? | B8: 2 | D8: CHƯA có. Sẽ đo ở pilot tháng 1.
A9: A5. Khách tự kiểm toán được danh sách job bị tính tiền? | B9: 4 | D9: Xuất CSV từng hóa đơn + trạng thái + người duyệt (thiết kế).
A10: Điểm Attribution trung bình | B10: =AVERAGE(B5:B9) -> 3.2 | C10: / 5 | D10: Ngưỡng CAO: ≥ 3,5.
A11: Mức Attribution | B11: =IF($B$10>=3.5,"CAO","THẤP") -> THẤP
A13: Autonomy — AI tự chạy hết một job hay cần người can thiệp giữa chừng? (chấm 1–5)
A14: U1. Tỷ lệ job hoàn thành không cần người (containment) ≥ 80%? | B14: 4 | D14: Ước tính ~80%, CHƯA đo (xem 1_Cost_Job S2).
A15: U2. AI tự đẩy bút toán vào phần mềm kế toán, không cần duyệt từng hóa đơn? | B15: 2 | D15: Không: kế toán duyệt hàng loạt trước khi hạch toán.
A16: U3. Khi AI sai, hệ thống tự phát hiện (ngưỡng tin cậy, quy tắc MST/tổng tiền)? | B16: 3 | D16: Có quy tắc cơ bản; chưa được hiệu chỉnh bằng dữ liệu thật.
A17: U4. Chạy nền/batch, không cần người ngồi cạnh? | B17: 5 | D17: Có: khách upload hoặc forward email, kết quả trả trong ngày.
A18: U5. Khách chấp nhận không duyệt từng job (rủi ro thuế, giá trị mỗi job thấp)? | B18: 2 | D18: Chưa: hạch toán sai kéo theo rủi ro thuế nên khách vẫn muốn duyệt.
A19: Điểm Autonomy trung bình | B19: =AVERAGE(B14:B18) -> 3.2 | C19: / 5 | D19: Ngưỡng CAO: ≥ 3,5.
A20: Mức Autonomy | B20: =IF($B$19>=3.5,"CAO","THẤP") -> THẤP
A22: Gợi ý của model (ma trận Attribution × Autonomy)
A23: Ma trận gợi ý | B23: =IF($B$11="CAO",IF($B$20="CAO","Outcome","Usage"),IF($B$20="CAO","Usage","Seat / Hybrid")) -> Seat / Hybrid
B24: Attribution CAO + Autonomy CAO → Outcome · CAO + THẤP → Usage · THẤP + CAO → Usage (an toàn) · THẤP + THẤP → Seat / Hybrid.
A26: Ba yếu tố ngoài ma trận
A27: 1. Thói quen chi trả của thị trường | B27: SME Việt Nam quen trả theo gói tháng hoặc theo số chứng từ, ít khi trả theo kết quả.
A28: 2. Khả năng dự đoán chi phí của khách | B28: Chủ doanh nghiệp muốn biết trước tháng này trả bao nhiêu. Phí nền cố định giúp họ dự toán, chỉ phần vượt gói mới thay đổi.
A29: 3. Ai chịu chi phí inference | B29: Tôi chịu tiền token. Phí nền giúp tôi vẫn thu đủ bù chi phí kể cả khi khách ít dùng.
A31: Chốt Value Metric
A32: Value Metric đã chọn | B32: Hybrid | C32: chọn | D32: Seat / Usage / Outcome / Hybrid.
A33: Đơn vị tính tiền cụ thể | B33: Phí nền theo tháng (kèm hạn mức hóa đơn hoàn thành, kết nối phần mềm kế toán, SLA trong ngày) + phí theo từng hóa đơn HOÀN THÀNH vượt gói. Chi tiết số ở 2_Pricing mục C.
A34: Market override (bắt buộc nếu khác gợi ý) | B34: Không lệch — lựa chọn nằm trong gợi ý "Seat / Hybrid" của ma trận.
A35: Kiểm tra khớp ma trận | B35: =IF(ISNUMBER(SEARCH($B$32,$B$23)),"✓ Khớp ma trận Attribution × Autonomy",IF(LEN($B$34)>30,"~ Lệch ma trận, có lý do thị trường","✗ Lệch ma trận và THIẾU lý do thị trường")) -> ✓ Khớp ma trận Attribution × Autonomy
A37: Decision Note — 3 câu
A38: 1. Tôi chọn đơn vị nào? | B38: ="Tôi chọn Hybrid: phí nền theo tháng (có sẵn "&'2_Pricing'!$B$32&" hóa đơn) cộng phí theo từng hóa đơn xử lý xong vượt gói." -> Tôi chọn Hybrid: phí nền theo tháng (có sẵn 350 hóa đơn) cộng phí theo từng hóa đơn xử lý xong vượt gói.
A39: 2. Attribution và Autonomy của tôi ở mức nào — bằng chứng gì? | B39: ="Attribution của tôi "&LOWER($B$11)&" ("&ROUND($B$10,1)&"/5) vì chưa có bộ eval từ 200 mẫu và chưa đo được thời gian xử lý trước khi dùng AI của khách. Autonomy cũng "&LOWER($B$20)&" ("&ROUND($B$19,1)&"/5) vì AI tự xong khoảng "&ROUND('1_Cost_Job'!$B$22*100,0)&"% (mới là ước tính) và kế toán vẫn duyệt hàng loạt." -> Attribution của tôi thấp (3.2/5) vì chưa có bộ eval từ 200 mẫu và chưa đo được thời gian xử lý trước khi dùng AI của khách. Autonomy cũng thấp (3.2/5) vì AI tự xong khoảng 80% (mới là ước tính) và kế toán vẫn duyệt hàng loạt.
A40: 3. Nếu chọn khác gợi ý của model, lý do thị trường là gì? | B40: ="Ma trận gợi ý "&$B$23&" và tôi chọn "&$B$32&", nên không có chỗ lệch. Tôi chưa bán theo Outcome vì chưa có số liệu chứng minh kết quả là do AI. Khi đo được AI tự xong từ "&ROUND('5_90Day_Plan'!$B$29*100,1)&"% trở lên trong 2 tháng, tôi sẽ xem lại." -> Ma trận gợi ý Seat / Hybrid và tôi chọn Hybrid, nên không có chỗ lệch. Tôi chưa bán theo Outcome vì chưa có số liệu chứng minh kết quả là do AI. Khi đo được AI tự xong từ 67.5% trở lên trong 2 tháng, tôi sẽ xem lại.
A42: 2 benchmark thật cùng loại job (kèm link nguồn, ngày kiểm tra 13/10/2026)
A43: Benchmark 1: sản phẩm | B43: Veryfi (trích xuất hóa đơn / biên lai)
A44: Value metric và giá hiện hành | B44: Hybrid: cam kết tối thiểu $500/tháng (mua được "<5k tài liệu/tháng") + $0,16 / hóa đơn, $0,08 / biên lai; cam kết 12 tháng giảm 1 cent mỗi tài liệu.
A45: Link nguồn | B45: https://www.veryfi.com/pricing/
A46: Benchmark 2: sản phẩm | B46: Dext Prepare (nhập liệu hóa đơn cho kế toán)
A47: Value metric và giá hiện hành | B47: Gói theo hạn mức: $25,21/tháng (US) cho 250 tài liệu/tháng và 5 user; kéo thanh trượt để tăng hạn mức; vượt hạn mức thì chưa trích xuất dữ liệu đến kỳ sau.
...

Sheet 4_Channel_Fit
A1: 4_Channel_Fit — Ngân sách CAC, số deal/AE/ngày, chốt đúng 1 kênh
A2: SẢN PHẨM GIẢ ĐỊNH (placeholder) — "HoaDonAI": AI nhập liệu và đối chiếu hóa đơn đầu vào cho SME Việt Nam. Thay các ô VÀNG bằng số liệu sản phẩm thật của bạn; mọi ô xám tự tính lại.
A4: 1. Ngân sách CAC = ARPU tháng × GM × số tháng payback cho phép
A5: ARPU / tháng | B5: ='2_Pricing'!$B$36 -> 64.571429 | C5: $ / khách | D5: Liên kết 2_Pricing mục C.
A6: Gross Margin | B6: ='2_Pricing'!$B$48 -> 0.69501545 | C6: % | D6: Liên kết 2_Pricing mục D.
A7: Phân khúc khách | B7: SMB | C7: chọn | D7: SMB / Mid-market / Enterprise.
A8: CAC payback cho phép | B8: =INDEX('6_Benchmarks'!$B$33:$B$35,MATCH($B$7,'6_Benchmarks'!$A$33:$A$35,0)) -> 12 | C8: tháng | D8: Bessemer 2024 (6_Benchmarks, mục D).
A9: NGÂN SÁCH CAC / KHÁCH | B9: =$B$5*$B$6*$B$8 -> 538.53769 | C9: $ / khách
A11: 2. Sales-Led có chạy được không? — số deal 1 AE phải chốt = Quota năm / ACV
A12: ACV (= ARPU × 12) | B12: =$B$5*12 -> 774.85714 | C12: $ / năm
A13: Quota / AE / năm | B13: 500000 | C13: $ | D13: Giả định gốc của đề.
A14: Chi phí fully-loaded 1 AE | B14: 100000 | C14: $ / năm | D14: Giả định gốc của đề.
A15: Tỷ lệ đạt quota | B15: 0.75 | C15: % | D15: Giả định gốc của đề.
A16: Số ngày làm việc / năm | B16: 250 | C16: ngày
A17: Số deal 1 AE phải chốt / năm | B17: =$B$13/$B$12 -> 645.28024 | C17: deal
A18: SỐ DEAL / AE / NGÀY LÀM VIỆC | B18: =$B$17/$B$16 -> 2.5811209 | C18: deal / ngày | D18: ≤ ~1 deal/ngày: khả thi; > 1: không chạy được dù tuyển sales giỏi đến đâu.
A19: Kết luận Sales-Led | B19: =IF($B$18<=1,"✓ Khả thi (≤ 1 deal/AE/ngày)","✗ KHÔNG CHẠY ĐƯỢC: > 1 deal/AE/ngày ở mức ACV này") -> ✗ KHÔNG CHẠY ĐƯỢC: > 1 deal/AE/ngày ở mức ACV này
A20: Chi phí AE / deal (chỉ lương AE, chưa gồm lead gen) | B20: =$B$14/($B$13*$B$15/$B$12) -> 206.62857 | C20: $ / deal | D20: Tham khảo.
A22: 3. CAC thực của motion có sales = Cost per opportunity / Win rate
A23: Cost per lead (theo phân khúc) | B23: =INDEX('6_Benchmarks'!$C$33:$C$35,MATCH($B$7,'6_Benchmarks'!$A$33:$A$35,0)) -> 500 | C23: $ | D23: ICONIQ 2026 (theo đề).
A24: Cost per opportunity (theo phân khúc) | B24: =INDEX('6_Benchmarks'!$D$33:$D$35,MATCH($B$7,'6_Benchmarks'!$A$33:$A$35,0)) -> 6300 | C24: $ | D24: ICONIQ 2026 (theo đề).
A25: Win rate | B25: 0.25 | C25: % | D25: Giả định của đề.
A26: CAC THỰC ƯỚC TÍNH | B26: =$B$24/$B$25 -> 25200 | C26: $ / khách
A27: Lệch so với ngân sách CAC | B27: =$B$26/$B$9 -> 46.793383 | C27: lần | D27: Ghi lại con số này — đây là bằng chứng chọn kênh.
A29: 4. Scorecard 3 kênh — 6 tiêu chí × 1–5 (chốt đúng 1 kênh)
A30: Tiêu chí | B30: PLG | C30: Sales-Led | D30: Partner-Led | E30: Lý do chấm
A31: 1. Ngân sách CAC phủ được CAC thực của kênh | B31: 4 | C31: 1 | D31: 4 | E31: PLG: CAC mục tiêu ≤ ngân sách, chưa đo. Sales-Led: CAC thực lệch hàng chục lần so với ngân sách (mục 3). Partner: phụ thuộc chia margin.
A32: 2. Khả thi về số deal/AE/ngày (hoặc không cần AE) | B32: 5 | C32: 1 | D32: 4 | E32: PLG không cần AE; Sales-Led > 1 deal/ngày/AE.
A33: 3. Khớp Pain Moment và điểm nhúng | B33: 4 | C33: 3 | D33: 3 | E33: Email-forward nằm đúng chỗ kế toán đang làm việc (hộp thư hóa đơn).
A34: 4. Tốc độ học trong 90 ngày với đội nhỏ | B34: 5 | C34: 2 | D34: 2 | E34: PLG cho vòng phản hồi hằng tuần; Partner cần đàm phán nhiều tuần.
A35: 5. Độ độc lập (ít phụ thuộc bên thứ ba) | B35: 5 | C35: 4 | D35: 1 | E35: Partner-Led: sống chết theo một nền tảng khác.
A36: 6. Khớp ARPU / ACV | B36: 5 | C36: 1 | D36: 4 | E36: ARPU ~$52/tháng quá thấp cho sales rep.
A37: Tổng điểm | B37: =SUM(B31:B36) -> 28 | C37: =SUM(C31:C36) -> 12 | D37: =SUM(D31:D36) -> 18
A38: KÊNH ĐÃ CHỐT (điểm cao nhất) | B38: =IF(COUNTIF(B37:D37,MAX(B37:D37))>1,"HÒA ĐIỂM — phải chốt thủ công 1 kênh",INDEX($B$30:$D$30,MATCH(MAX(B37:D37),B37:D37,0))) -> PLG
A39: Lý do chốt kênh | B39: ="Tôi chọn PLG vì con số cho thấy bán qua sales không chạy được. Mỗi khách trả khoảng $"&ROUND($B$5,0)&"/tháng nên ngân sách CAC chỉ $"&ROUND($B$9,0)&". Bán qua sales rep cần "&ROUND($B$18,2)&" deal/người/ngày, và CAC thực khoảng $"&ROUND($B$26,0)&", gấp "&ROUND($B$27,0)&" lần ngân sách. Tôi không chọn Partner-Led vì chưa có tên đối tác nào và chưa nói chuyện với ai. PLG hợp nhất vì khách chỉ cần chuyển tiếp email hóa đơn, không phải cài thêm gì." -> Tôi chọn PLG vì con số cho thấy bán qua sales không chạy được. Mỗi khách trả khoảng $65/tháng nên ngân sách CAC chỉ $539. Bán qua sales rep cần 2.58 deal/người/ngày, và CAC thực khoảng $25200, gấp 47 lần ngân sách. Tôi không chọn Partner-Led vì chưa có tên đối tác nào và chưa nói chuyện với ai. PLG hợp nhất vì khách chỉ cần chuyển tiếp email hóa đơn, không phải cài thêm gì.
A41: 5. Nếu rơi vào vùng không khả thi — chọn 1 trong 3 lối thoát
A42: Lối thoát đã chọn | B42: Giảm giá xuống | C42: chọn | D42: Giảm giá xuống / Tăng giá lên / Đi Partner-Led.
A43: Việc cụ thể trong 30 ngày tới | B43: Tôi dựng trang đăng ký và hộp thư nhận email chuyển tiếp, rồi nhờ 10 kế toán dùng thử. Nếu dưới 5 người gửi hóa đơn thật trong 14 ngày, tôi dừng và quay lại phỏng vấn.
A45: KẾT QUẢ TRẠM 4 — các con số bắt buộc
A46: [ ✓ ] Ngân sách CAC / khách | B46: =$B$9 -> 538.53769 | C46: $
...

Sheet 5_90Day_Plan
A1: 5_90Day_Plan — Pain Moment, kế hoạch 90 ngày, checklist Evidence Pack
A2: SẢN PHẨM GIẢ ĐỊNH (placeholder) — "HoaDonAI": AI nhập liệu và đối chiếu hóa đơn đầu vào cho SME Việt Nam. Thay các ô VÀNG bằng số liệu sản phẩm thật của bạn; mọi ô xám tự tính lại. Tên người chịu trách nhiệm là vai trò giả định — thay bằng tên thật trong nhóm của bạn.
A4: Pain Moment = MẤY GIỜ + ĐANG LÀM GÌ + DÙNG APP NÀO
A5: Mấy giờ | B5: Ngày 17–20 hàng tháng, vài ngày trước hạn kê khai thuế GTGT tháng (hạn là ngày 20 — cần xác minh với cơ quan thuế).
A6: Đang làm gì | B6: Kế toán đang gom hơn 300 hóa đơn đầu vào còn tồn trong hộp thư để nhập liệu, hạch toán và đối chiếu trước khi lập tờ khai.
A7: Dùng app nào | B7: Gmail hoặc Outlook (hóa đơn điện tử về qua email) và phần mềm kế toán / Excel.
A8: Pain Moment (câu hoàn chỉnh) | B8: ="Lúc "&$B$5&" — "&$B$6&" — trên "&$B$7 -> Lúc Ngày 17–20 hàng tháng, vài ngày trước hạn kê khai thuế GTGT tháng (hạn là ngày 20 — cần xác minh với cơ quan thuế). — Kế toán đang gom hơn 300 hóa đơn đầu vào còn tồn trong hộp thư để nhập liệu, hạch toán và đối chiếu trước khi lập tờ khai. — trên Gmail hoặc Outlook (hóa đơn điện tử về qua email) và phần mềm kế toán / Excel.
A9: Điểm nhúng (bề mặt tích hợp cụ thể) | B9: Hộp thư nhận email-forward riêng cho từng công ty (hoa-don@ten-cong-ty.…) + add-on Gmail/Outlook "Gửi sang HoaDonAI" — khách không phải mở website mới, không học workflow mới. Không phải "website của chúng tôi".
A11: Kế hoạch 90 ngày — 3 giai đoạn (số + người chịu trách nhiệm)
A12: Tỷ lệ đăng ký → trả phí (giả định để tính phễu) | B12: 0.1 | C12: % | D12: GIẢ ĐỊNH, tháng 1–2 sẽ đo thật.
A13: THÁNG 1 — Hiểu sâu, làm tận tay | B13: Giá trị | C13: Đơn vị | D13: Ghi chú
A14: Số khách pilot | B14: 8 | C14: khách | D14: Tận tay: bạn trực tiếp đặt lịch, cài hộp thư, ngồi xem họ dùng.
A15: Ai đi gặp | B15: Founder/PM (bạn): 8 buổi onboarding tại chỗ + 1 buổi review cuối tháng; Dev 1 hỗ trợ kỹ thuật.
A16: Dữ liệu cần thu | B16: 2000 | C16: hóa đơn có nhãn | D16: Hóa đơn thật + bản kế toán sửa lại → đưa vào bộ eval; đo baseline thời gian/hóa đơn của khách.
A17: Chi cho quảng cáo | B17: 0 | C17: $ | D17: Tháng 1 là giai đoạn HỌC, không scale. Ô = 0 có lý do.
A18: THÁNG 2–3 — Đòn bẩy qua kênh đã chọn (PLG) | B18: Giá trị | C18: Đơn vị | D18: Ghi chú
A19: Mục tiêu khách trả phí cuối tháng 3 | B19: 15 | C19: khách
A20: Số đăng ký cần có | B20: =$B$19/$B$12 -> 150 | C20: đăng ký | D20: = mục tiêu / tỷ lệ chuyển đổi.
A21: Ngân sách thu hút khách tối đa trong 90 ngày | B21: =$B$19*'4_Channel_Fit'!$B$9 -> 8078.0653 | C21: $ | D21: = khách mục tiêu × ngân sách CAC (4_Channel_Fit). Vượt mức này là kênh không bền.
A22: Volume ngụ ý (job thử / tháng) | B22: =$B$19*'2_Pricing'!$B$39 -> 9750 | C22: job | D22: Phải gần với giả định ở 1_Cost_Job S2.
A23: Khớp với 1_Cost_Job? | B23: =IF(ABS($B$22/'1_Cost_Job'!$B$21-1)<=0.1,"✓ Volume ngụ ý nằm trong ±10% so với giả định 10.000 job/tháng","✗ Volume ngụ ý lệch > 10% so với giả định ở 1_Cost_Job S2 — chỉnh một trong hai") -> ✓ Volume ngụ ý nằm trong ±10% so với giả định 10.000 job/tháng
A24: Cơ chế nhân rộng · KPI | B24: Cơ chế: tự phục vụ qua email-forward + giới thiệu giữa các kế toán dùng chung khách. KPI hằng tuần: đăng ký mới, % forward ≥ 20 hóa đơn trong 7 ngày đầu, containment đo được, ca QA phát hiện sai.
A25: Người chịu trách nhiệm | B25: Founder/PM (bạn): kênh PLG và phễu. Dev 1: containment/eval. Dev 2 hoặc bạn kiêm: hỗ trợ khách.
A26: Tiêu chí dừng (kill) sau 14 ngày | B26: Dưới 5 trong 10 kế toán concierge test forward hóa đơn thật → dừng, quay lại phỏng vấn Pain Moment.
A27: THÁNG 4+ — Mở rộng, chỉ sau khi thắng tuyệt đối 1 ngách | B27: Giá trị | C27: Đơn vị | D27: Ghi chú
A28: Ngách đang thắng (điều kiện mở rộng) | B28: SME thương mại/phân phối có 300–1.000 hóa đơn đầu vào/tháng. Chỉ mở ngách khác khi ngách này đạt cả ba cổng bên dưới.
A29: Cổng 1: containment đo được ≥ | B29: ='2_Pricing'!$B$64+0.1 -> 0.6746103 | C29: % | D29: = breakeven containment + 10 điểm % (2_Pricing mục E). Đo bằng eval, không phải ước tính.
A30: Cổng 2: GM thực tế ≥ | B30: ='2_Pricing'!$B$45 -> 0.6 | C30: % | D30: Đo từ chi phí thật, không phải giả định.
A31: Ngách tiếp theo · dựa trên bằng chứng nào | B31: Văn phòng kế toán thuê ngoài (1 văn phòng phục vụ nhiều SME) — chỉ khi 15 khách đầu có churn thấp và ≥ 2 khách nói họ giới thiệu được cho văn phòng kế toán của mình. Partner-Led xem xét sau cổng này.
A33: Evidence Pack — 3 tài sản bằng văn bản để Procurement và IT dám ký
A34: Ô nào chưa có thì ghi ai làm + deadline, không bỏ trống. Một Evidence Pack thành thật về khoảng trống tốt hơn một Evidence Pack bịa.
A35: Tài sản | B35: Trạng thái | D35: Deadline | E35: Chịu trách nhiệm | G35: Nội dung hoặc cách đo
A36: Eval Results | B36: CHƯA CÓ | D36: 46336 | E36: Dev 1 | G36: Xây gold set 300 hóa đơn gán nhãn kép; đo field accuracy, % hạch toán đúng tài khoản, containment. Câu cần điền: "xử lý đúng __%; __% còn lại chuyển người".
A37: Procurement Q&A | B37: BẢN NHÁP | D37: 46322 | E37: Founder/PM (bạn) | G37: Có bản nháp 3 câu trả lời ở các dòng bên dưới; cần Dev 1 xác nhận khả thi kỹ thuật trước khi gửi khách.
A38: Pilot Report | B38: CHƯA CÓ | D38: 46371 | E38: Founder/PM (bạn) | G38: Pilot với 8 SME bắt đầu 03/11/2026 (tên khách: chưa chốt). Mẫu: "__ tuần, __ lượt, tỷ lệ thành công __%, tiết kiệm __".
A40: Procurement Q&A — bản nháp trả lời 3 câu hỏi của Procurement/IT
A41: 1. AI này có hallucinate không? Nếu nó nói sai với khách của tôi thì sao? | B41: AI có thể sai. Hóa đơn nào AI không chắc sẽ chuyển cho kế toán duyệt, và không hóa đơn nào được hạch toán nếu chưa qua kiểm tra mã số thuế, tổng tiền và thuế. Tỷ lệ chính xác tôi sẽ công bố sau khi có bộ eval (dự kiến 10/11/2026). Hiện tôi chưa có con số đó.
A42: 2. Data của tôi có bị dùng để train model không? | B42: Dữ liệu của khách chỉ dùng để xử lý hóa đơn cho chính họ, không dùng để huấn luyện model. Tôi sẽ ghi điều này vào hợp đồng sau khi kiểm tra điều khoản của nhà cung cấp LLM.
A43: 3. Startup này chết thì data của tôi ở đâu? | B43: Khách tải được toàn bộ hóa đơn và bút toán (CSV/XML) bất cứ lúc nào, và dữ liệu bị xóa sau 30 ngày khi hết hợp đồng. Tính năng tải dữ liệu tôi dự kiến làm xong trước 30/11/2026.

Sheet 6_Benchmarks
A1: 6_Benchmarks — Bảng giá & benchmark tham chiếu (CHỈ ĐỌC)
A2: Dòng "✓ kiểm tra 13/10/2026" = đã mở trang giá gốc ngày làm bài. Dòng "theo đề Lab, chưa kiểm tra lại" = số liệu chốt 26/08/2026 trong đề (§3.5), mô hình này không dùng. ⌛ = giá khuyến mại có hạn. Mọi con số giá phải có ngày kiểm tra.
A4: A. Giá API LLM — Anthropic · ✓ kiểm tra 13/10/2026 · USD / 1 triệu token (MTok)
A5: Model | B5: Input | C5: Cache write 5 phút | D5: Cache read | E5: Output | F5: Batch input | G5: Batch output | H5: Ngày kiểm tra | I5: Nguồn / ghi chú
A6: Claude Haiku 5.5 | B6: 0.1 | C6: 0.125 | D6: 0.01 | E6: 0.5 | F6: 0.05 | G6: 0.25 | H6: 46308 | I6: Mức cho prompt ≤ 100.000 token; prompt dài hơn tính $0,50 / $2,50.
A7: Claude Haiku 4.5 | B7: 1 | C7: 1.25 | D7: 0.1 | E7: 5 | F7: 0.5 | G7: 2.5 | H7: 46308 | I7: Model dùng trong worked example của đề.
A8: Claude Sonnet 5.5 | B8: 2 | C8: 2.5 | D8: 0.1 | E8: 10 | F8: 1 | G8: 5 | H8: 46308 | I8: Cache hit = 0,05× giá input (trang giá, chú thích 2). MODEL CƠ SỞ của mô hình này.
A9: Claude Sonnet 5 | B9: 2 | C9: 2.5 | D9: 0.2 | E9: 10 | F9: 1 | G9: 5 | H9: 46308 | I9: Giá $2/$10 từng là giá giới thiệu đến 31/08/2026, nay là giá chuẩn; đợt tăng lên $3/$15 sẽ không xảy ra.
A10: Claude Opus 5.5 | B10: 4 | C10: 5 | D10: 0.2 | E10: 20 | F10: 2 | G10: 10 | H10: 46308 | I10: Cache hit = 0,05× giá input.
A11: Claude Opus 5 | B11: 5 | C11: 6.25 | D11: 0.5 | E11: 25 | F11: 2.5 | G11: 12.5 | H11: 46308 | I11: Khớp bảng của đề (26/08/2026).
A12: Claude Fable 5.1 | B12: 10 | C12: 12.5 | D12: 0.25 | E12: 50 | F12: 5 | G12: 25 | H12: 46308 | I12: Cache hit = 0,025× giá input.
A13: Nguồn: https://platform.claude.com/docs/en/about-claude/pricing (mở ngày 13/10/2026). So với bảng 26/08/2026 trong đề: trang giá nay có thêm Opus 5.5 ($4/$20), Sonnet 5.5 và Haiku 5.5 ($0,10/$0,50). Haiku 4.5 và Opus 5 không đổi. Batch API giảm 50% cả input lẫn output; hệ số cache cộng dồn với Batch.
A15: B. Giá API khác (dùng cho biến thể thoại / đối chiếu nhà cung cấp)
A16: Hạng mục | B16: Giá và ghi chú | H16: Ngày kiểm tra | I16: Nguồn
A17: OpenAI GPT-5.6 Sol ⌛ | B17: ✓ $4 input / $20 output; cached input $0,40 mỗi 1M token. Trang giá ghi giá khuyến mại "ít nhất đến 21/11/2026". Mức list $5/$30 theo đề Lab, CHƯA xác nhận lại (trang chỉ cho thấy tầng >272K token: $8 / $30). | H17: 46308 | I17: https://developers.openai.com/api/docs/pricing
A18: Google Gemini 3.8 Flash ⌛ (đề ghi 3.7 Flash) | B18: ✓ $0,75 input / $3,75 output đến 31/12/2026, sau đó $1,50 / $7,50. Trang giá hiện liệt kê 3.8 Flash và 3.6 Flash, không còn 3.7 Flash; không có giá audio riêng cho model này. | H18: 46308 | I18: https://ai.google.dev/gemini-api/docs/pricing
A19: Deepgram Nova-3 ⌛ | B19: Theo đề Lab: pre-recorded $0,0043/phút; streaming list $0,0077/phút, khuyến mại $0,0048/phút. CHƯA kiểm tra lại. Sản phẩm này không dùng thoại. | H19: 46260 | I19: https://deepgram.com/pricing
A20: AssemblyAI Universal-2 | B20: Theo đề Lab: async $0,0025/phút. CHƯA kiểm tra lại. | H20: 46260 | I20: https://www.assemblyai.com/pricing
A21: Google Cloud STT / TTS | B21: Theo đề Lab: STT tính theo từng kênh audio; TTS Standard $4 / 1M ký tự, Studio $160 / 1M ký tự. CHƯA kiểm tra lại. | H21: 46260 | I21: https://cloud.google.com/speech-to-text/pricing
A22: ElevenLabs TTS | B22: Theo đề Lab: v3/v2 Multilingual $100 / 1M ký tự; Flash/Turbo $50 / 1M ký tự. CHƯA kiểm tra lại. | H22: 46260 | I22: https://elevenlabs.io/pricing/api
A24: C. Giá sản phẩm AI (benchmark Value Metric)
A25: Sản phẩm | B25: Đơn vị tính tiền và giá | H25: Ngày kiểm tra | I25: Nguồn
A26: Veryfi (trích xuất hóa đơn / biên lai) ✓ | B26: Hybrid: cam kết tối thiểu $500/tháng, mua được "<5k tài liệu/tháng"; $0,16 / hóa đơn, $0,08 / biên lai. Cam kết 12 tháng: giảm 1 cent mỗi tài liệu. Gói Free: tối đa 100 tài liệu/tháng. | H26: 46308 | I26: https://www.veryfi.com/pricing/
A27: Dext Prepare (nhập liệu hóa đơn cho kế toán) ✓ | B27: Gói theo hạn mức tài liệu: $25,21/tháng (US, chưa thuế) cho 250 tài liệu/tháng và 5 user; kéo thanh trượt để tăng hạn mức. Vượt hạn mức: vẫn upload được nhưng chưa trích xuất dữ liệu đến kỳ thanh toán sau. AI Assist add-on $10,5/tháng đến 31/01/2027 ⌛. | H27: 46308 | I27: https://www.dext.com/us/pricing/prepare-direct/
A28: Intercom Fin | B28: Theo đề Lab: Outcome — $0,99 / resolution. CHƯA kiểm tra lại. Khác loại job (CSKH), chỉ dùng làm đối chiếu Outcome. | H28: 46260 | I28: https://fin.ai/pricing/
A29: GitHub Copilot, Salesforce Agentforce, Zendesk, Notion, Cursor, Clay, Sierra | B29: Theo đề Lab §3.5 (chốt 26/08/2026): xem link trong đề. CHƯA kiểm tra lại; không dùng trong mô hình này. | H29: 46260 | I29: (xem Lab §3.5)
A31: D. Benchmark GTM theo phân khúc (dùng cho 4_Channel_Fit) — theo đề Lab §3.5, chưa kiểm tra lại
A32: Phân khúc | B32: CAC payback cho phép (tháng) | C32: Cost per lead ($) | D32: Cost per opportunity ($) | H32: Ngày kiểm tra | I32: Nguồn
A33: SMB | B33: 12 | C33: 500 | D33: 6300 | H33: 46260 | I33: Payback: Bessemer, Scaling to $100M (cập nhật 2024). Cost per lead/opportunity: ICONIQ, The State of GTM in 2026 (tr.22) — số liệu theo đề.
A34: Mid-market | B34: 18 | C34: 600 | D34: 8000 | H34: 46260 | I34: Payback: Bessemer, Scaling to $100M (cập nhật 2024). Cost per lead/opportunity: ICONIQ, The State of GTM in 2026 (tr.22) — số liệu theo đề.
A35: Enterprise | B35: 24 | C35: 800 | D35: 11200 | H35: 46260 | I35: Payback: Bessemer, Scaling to $100M (cập nhật 2024). Cost per lead/opportunity: ICONIQ, The State of GTM in 2026 (tr.22) — số liệu theo đề.
A37: Gross Margin AI-native | B37: ICONIQ 2026 State of AI: ~45% (2025) → ~53% (2026E) → ~59% (2027E). Bessemer State of the Cloud 2024: vertical AI ~65%. Cloud truyền thống 60–80%. GM > 85% ở mô hình AI thường nghĩa là quên một khoản chi phí.
A38: LTV:CAC và payback | B38: David Skok, SaaS Metrics 2.0: LTV:CAC > 3 (tốt nhất 7–8×); CAC payback tốt nhất 5–7 tháng.
A39: Ngưỡng ACV cho Inside Sales | B39: Tomasz Tunguz (2016): ACV tối thiểu ~$3.000 để nuôi được inside sales team. Tunguz (2017) bác bỏ giả thuyết "vùng chết ACV" bằng dữ liệu công ty đại chúng. Không có nguồn nào chuẩn hóa "vùng chết $50–$1.000"; đó là heuristic, không phải benchmark.
A40: Tỷ giá USD/VND | B40: Trung bình 36 ngân hàng 06/07/2026: 26.252 (webgia.com/ngoai-te/usd/). Vietcombank 05/07/2026: mua 26.073 / bán 26.463. Chưa tìm được tỷ giá tháng 10/2026 — cập nhật theo Vietcombank ngày nộp bài.
